#VRML_SIM R2023b utf8

EXTERNPROTO "https://raw.githubusercontent.com/cyberbotics/webots/R2023b/projects/objects/backgrounds/protos/TexturedBackground.proto"
EXTERNPROTO "https://raw.githubusercontent.com/cyberbotics/webots/R2023b/projects/objects/backgrounds/protos/TexturedBackgroundLight.proto"
EXTERNPROTO "https://raw.githubusercontent.com/cyberbotics/webots/R2023b/projects/objects/floors/protos/RectangleArena.proto"
EXTERNPROTO "https://raw.githubusercontent.com/cyberbotics/webots/R2023b/projects/objects/drinks/protos/Can.proto"
EXTERNPROTO "https://raw.githubusercontent.com/cyberbotics/webots/R2023b/projects/objects/fruits/protos/Apple.proto"
EXTERNPROTO "https://raw.githubusercontent.com/cyberbotics/webots/R2023b/projects/objects/kitchen/breakfast/protos/JamJar.proto"
EXTERNPROTO "https://raw.githubusercontent.com/cyberbotics/webots/R2023b/projects/objects/kitchen/breakfast/protos/BiscuitBox.proto"
EXTERNPROTO "https://raw.githubusercontent.com/cyberbotics/webots/R2023b/projects/objects/obstacles/protos/OilBarrel.proto"

WorldInfo {
  info [
    "Example use of a color Camera device with recognition capability."
  ]
  title "Camera Image Recognition"
}
Viewpoint {
  orientation 0.4958124374780919 0.010660951898188492 -0.8683641925751301 3.286909324731093
  position 1.4900753034353165 -0.22501457698418567 2.572708402786278
}
TexturedBackground {
}
TexturedBackgroundLight {
}
RectangleArena {
}
Can {
  translation -0.267626 -0.290201 0.060961710860935485
  rotation -1.255284180414606e-17 4.124109946487355e-17 1 3.14159
}
Apple {
  translation 0.221872 -0.277666 0.049764791394518226
}
Apple {
  translation 0.428276 -0.291241 0.049764791394518226
  name "apple(1)"
}
JamJar {
  translation -0.314033 0.288298 0
  rotation 0 0 -1 1.0472
  mass 0
}
BiscuitBox {
  translation 0.372915 -0.247523 0.09
  rotation 0.6947461893666473 -0.1861560507404686 -0.6947471893669199 -2.773495
  size 0.17 0.33 0.04
  mass 0
}
OilBarrel {
  translation 0.122868 0.40231 0.07
  rotation 0 0 1 1.5708
  height 0.14
  radius 0.06
}
OilBarrel {
  translation 0.182198 0.278521 0.07
  rotation 0 0 1 1.5708
  name "oil barrel(1)"
  height 0.14
  radius 0.06
}
OilBarrel {
  translation 0.318097 0.364876 0.07
  rotation 0 0 1 1.5708
  name "oil barrel(2)"
  height 0.14
  radius 0.06
}
OilBarrel {
  translation 0.368241 0.196561 0.07
  rotation 0 0 1 1.5708
  name "oil barrel(3)"
  height 0.14
  radius 0.06
}
Robot {
  translation 0.0011576155249116086 0.00034293623686821353 -0.0002342314279448962
  rotation 0.014151025103158382 0.005868891497545104 -0.9998826454145106 2.3553333712987037
  children [
    Pose {
      translation 0 0 0.0415
      rotation 0 0 1 -1.570796
      children [
        Shape {
          appearance PBRAppearance {
            baseColor 0.0820075 0.364731 0.8
            roughness 1
            metalness 0
          }
          geometry DEF BODY Cylinder {
            height 0.08
            radius 0.045
          }
        }
      ]
    }
    HingeJoint {
      jointParameters HingeJointParameters {
        position -97.85272797957235
        axis 0 1 0
        anchor 0 0 0.025
      }
      device [
        RotationalMotor {
          name "left wheel motor"
          consumptionFactor 70
        }
        PositionSensor {
          name "left wheel sensor"
        }
      ]
      endPoint Solid {
        translation 0 0.04499999999999999 0.025
        rotation -0.6822325307566848 0.6822327178837921 -0.2629016786295278 2.6274244148765558
        children [
          DEF WHEEL Pose {
            rotation 0.577656895078166 0.5771968951617173 -0.5771968951617173 -2.093935
            children [
              Shape {
                appearance PBRAppearance {
                  baseColor 1 0 0
                  roughness 1
                  metalness 0
                }
                geometry Cylinder {
                  height 0.01
                  radius 0.025
                }
              }
            ]
          }
        ]
        name "left wheel"
        boundingObject USE WHEEL
        physics DEF PHYSICS_WHEEL Physics {
          density -1
          mass 0.05
        }
        linearVelocity 0.02416987384119371 0.023662912905057693 -3.7096018914461285e-08
        angularVelocity -1.0482116296963881 1.0731027209284094 0.7557238279532892
      }
    }
    HingeJoint {
      jointParameters HingeJointParameters {
        position 97.85269460084794
        axis 0 1 0
        anchor 0 0 0.025
      }
      device [
        RotationalMotor {
          name "right wheel motor"
          consumptionFactor 70
        }
        PositionSensor {
          name "right wheel sensor"
        }
      ]
      endPoint Solid {
        translation 0 -0.045 0.025
        rotation 0.6914182101848395 -0.6914181476669049 -0.20947984080015716 2.728604775699375
        children [
          USE WHEEL
        ]
        name "right wheel"
        boundingObject USE WHEEL
        physics USE PHYSICS_WHEEL
        linearVelocity -0.024294458238355635 -0.023661184706363483 -8.111236482679526e-09
        angularVelocity 1.048209162306324 -1.0730992505216252 0.7557263212661322
      }
    }
    DistanceSensor {
      translation 0.042 0.02 0.063
      rotation 0 0 -1 -0.499205
      children [
        DEF SENSOR Pose {
          rotation 0.577656895078166 0.5771968951617173 -0.5771968951617173 -2.093935
          children [
            Shape {
              appearance PBRAppearance {
                baseColor 0.975691 0.981481 0.0252992
                roughness 1
                metalness 0
              }
              geometry Cylinder {
                height 0.004
                radius 0.008
              }
            }
          ]
        }
      ]
      name "ds0"
      lookupTable [
        0 1024 0
        0.05 1024 0
        0.15 0 0
      ]
      numberOfRays 2
      aperture 1
    }
    DistanceSensor {
      translation 0.042 -0.02 0.063
      rotation 0 0 1 -0.500795
      children [
        USE SENSOR
      ]
      name "ds1"
      lookupTable [
        0 1024 0
        0.05 1024 0
        0.15 0 0
      ]
      numberOfRays 2
      aperture 1
    }
    Shape {
      appearance PBRAppearance {
        baseColor 0.8 0.8 0.8
        baseColorMap ImageTexture {
          url [
            "https://raw.githubusercontent.com/cyberbotics/webots/R2023b/projects/samples/devices/worlds/textures/mybot.png"
          ]
        }
        roughness 0.5
        metalness 0
      }
      geometry IndexedFaceSet {
        coord Coordinate {
          point [
            0.0435 -0.015 0.038
            0.0435 -0.015 0.023
            0.0455 0 0.023
            0.0435 0.015 0.023
            0.0435 0.015 0.038
            0.0455 0 0.038
          ]
        }
        texCoord TextureCoordinate {
          point [
            0 0
            0.5 0
            1 0
            1 1
            0.5 1
            0 1
          ]
        }
        coordIndex [
          0, 1, 2, 5, -1, 5, 2, 3, 4, -1
        ]
        texCoordIndex [
          5, 0, 1, 4, -1, 4, 1, 2, 3, -1
        ]
        creaseAngle 0.9
      }
    }
    Camera {
      translation 0.04 0 0.0915
      children [
        Pose {
          translation -0.015 0 0
          rotation -0.5771968951617173 -0.577656895078166 -0.5771968951617173 -2.093935
          children [
            Shape {
              appearance PBRAppearance {
                roughness 1
                metalness 0
              }
              geometry Cylinder {
                height 0.03
                radius 0.01
              }
            }
          ]
        }
      ]
      fieldOfView 1.0472
      width 256
      height 128
      antiAliasing TRUE
      recognition Recognition {
        frameColor 0.929412 0.831373 0
        frameThickness 3
      }
    }
  ]
  name "MyBot"
  boundingObject Pose {
    translation 0 0 0.0415
    rotation 0 0 1 -1.570796
    children [
      USE BODY
    ]
  }
  physics Physics {
    density -1
    mass 0.5
  }
  controller "camera_recognition"
  linearVelocity 0.00018343015232539527 -0.0002504047092326919 -3.3250074695595615e-09
  angularVelocity -1.2322277669426555e-06 1.7321876060589641e-06 0.7516282890739162
}
