#VRML_SIM R2023b utf8

EXTERNPROTO "https://raw.githubusercontent.com/cyberbotics/webots/R2023b/projects/objects/backgrounds/protos/TexturedBackground.proto"
EXTERNPROTO "https://raw.githubusercontent.com/cyberbotics/webots/R2023b/projects/objects/backgrounds/protos/TexturedBackgroundLight.proto"
EXTERNPROTO "https://raw.githubusercontent.com/cyberbotics/webots/R2023b/projects/objects/factory/containers/protos/WoodenBox.proto"
EXTERNPROTO "https://raw.githubusercontent.com/cyberbotics/webots/R2023b/projects/objects/floors/protos/Floor.proto"
EXTERNPROTO "https://raw.githubusercontent.com/cyberbotics/webots/R2023b/projects/appearances/protos/ThreadMetalPlate.proto"
EXTERNPROTO "https://raw.githubusercontent.com/cyberbotics/webots/R2023b/projects/vehicles/protos/abstract/GenericTireAppearance.proto"

WorldInfo {
  basicTimeStep 16
}
Viewpoint {
  orientation 0.21334742830078432 4.410534437671032e-16 -0.9769763942068621 3.1415926535897953
  position 1.6771609302390524 -0.014910389497949593 0.8070635531592463
}
TexturedBackground {
}
TexturedBackgroundLight {
}
Floor {
  size 1 1
  tileSize 0.3 0.3
}
WoodenBox {
  translation 0.323941 0.29124 0.05
  size 0.1 0.1 0.1
}
WoodenBox {
  translation -0.258126 -0.283445 0.05
  name "wooden box(2)"
  size 0.1 0.1 0.1
}
WoodenBox {
  translation 0.348369 -0.358911 0.05
  name "wooden box(3)"
  size 0.1 0.1 0.1
}
WoodenBox {
  translation -0.351374 0.238716 0.05
  name "wooden box(1)"
  size 0.1 0.1 0.1
}
Solid {
  translation -0.01 0.51 0.025
  children [
    DEF WALL_SHAPE Shape {
      appearance PBRAppearance {
        baseColor 0.219608 0.105882 0.0901961
        roughness 1
        metalness 0
      }
      geometry Box {
        size 1.02 0.02 0.05
      }
    }
  ]
  name "WALL_1"
  boundingObject USE WALL_SHAPE
}
Solid {
  translation 0.01 -0.51 0.025
  children [
    USE WALL_SHAPE
  ]
  name "WALL_2"
  boundingObject USE WALL_SHAPE
}
Solid {
  translation 0.51 0.01 0.025
  rotation 0 0 1 -1.5707953071795862
  children [
    USE WALL_SHAPE
  ]
  name "WALL_3"
  boundingObject USE WALL_SHAPE
}
Solid {
  translation -0.51 -0.01 0.025
  rotation 0 0 1 -1.5707953071795862
  children [
    USE WALL_SHAPE
  ]
  name "WALL_4"
  boundingObject USE WALL_SHAPE
}
Robot {
  translation 0 0 0.0411658
  children [
    DEF BODY Shape {
      appearance ThreadMetalPlate {
      }
      geometry Box {
        size 0.2 0.1 0.05
      }
    }
    DEF WHEEL_1 HingeJoint {
      jointParameters HingeJointParameters {
        axis 0 1 0
        anchor 0.05 0.06 0
      }
      device [
        RotationalMotor {
          name "wheel_1"
        }
      ]
      endPoint Solid {
        translation 0.05 0.06 0
        rotation 1 0 0 1.5708
        children [
          DEF WHEEL Shape {
            appearance GenericTireAppearance {
            }
            geometry Cylinder {
              height 0.02
              radius 0.04
              subdivision 24
            }
          }
        ]
        name "wheel_1"
        boundingObject USE WHEEL
        physics Physics {
        }
      }
    }
    DEF WHEEL_2 HingeJoint {
      jointParameters HingeJointParameters {
        axis 0 1 0
        anchor 0.05 -0.06 0
      }
      device [
        RotationalMotor {
          name "wheel_2"
        }
      ]
      endPoint Solid {
        translation 0.05 -0.06 0
        rotation 1 0 0 1.5708
        children [
          USE WHEEL
        ]
        name "wheel_2"
        boundingObject USE WHEEL
        physics Physics {
        }
      }
    }
    DEF WHEEL_3 HingeJoint {
      jointParameters HingeJointParameters {
        axis 0 1 0
        anchor -0.05 0.06 0
      }
      device [
        RotationalMotor {
          name "wheel_3"
        }
      ]
      endPoint Solid {
        translation -0.05 0.06 0
        rotation 1 0 0 1.5708
        children [
          USE WHEEL
        ]
        name "wheel_3"
        boundingObject USE WHEEL
        physics Physics {
        }
      }
    }
    DEF WHEEL_4 HingeJoint {
      jointParameters HingeJointParameters {
        axis 0 1 0
        anchor -0.05 -0.06 0
      }
      device [
        RotationalMotor {
          name "wheel_4"
        }
      ]
      endPoint Solid {
        translation -0.05 -0.06 0
        rotation 1 0 0 1.5708
        children [
          USE WHEEL
        ]
        name "wheel_4"
        boundingObject USE WHEEL
        physics Physics {
        }
      }
    }
  ]
  name "4_wheels_robot"
  boundingObject USE BODY
  physics Physics {
  }
}
