#VRML_SIM R2023b utf8

EXTERNPROTO "https://raw.githubusercontent.com/cyberbotics/webots/R2023b/projects/objects/backgrounds/protos/TexturedBackground.proto"
EXTERNPROTO "https://raw.githubusercontent.com/cyberbotics/webots/R2023b/projects/objects/backgrounds/protos/TexturedBackgroundLight.proto"
EXTERNPROTO "https://raw.githubusercontent.com/cyberbotics/webots/R2023b/projects/objects/factory/containers/protos/WoodenBox.proto"
EXTERNPROTO "https://raw.githubusercontent.com/cyberbotics/webots/R2023b/projects/objects/floors/protos/Floor.proto"
EXTERNPROTO "https://raw.githubusercontent.com/cyberbotics/webots/R2023b/projects/appearances/protos/ThreadMetalPlate.proto"
EXTERNPROTO "https://raw.githubusercontent.com/cyberbotics/webots/R2023b/projects/vehicles/protos/abstract/GenericTireAppearance.proto"
EXTERNPROTO "https://raw.githubusercontent.com/cyberbotics/webots/R2023b/projects/appearances/protos/Fabric.proto"
EXTERNPROTO "../protos/FourWheelsRobot.proto"

WorldInfo {
  basicTimeStep 16
}
Viewpoint {
  orientation 0.24316220881503875 0.001823750761567873 -0.9699839246798634 3.127042878588287
  position 1.6886874695592522 0.08916969455081772 0.8966927064287511
}
TexturedBackground {
}
TexturedBackgroundLight {
}
Floor {
  size 1 1
  tileSize 0.3 0.3
}
WoodenBox {
  translation 0.323941 0.29124 0.05
  size 0.1 0.1 0.1
}
WoodenBox {
  translation -0.258126 -0.283445 0.05
  name "wooden box(2)"
  size 0.1 0.1 0.1
}
WoodenBox {
  translation 0.348369 -0.358911 0.05
  name "wooden box(3)"
  size 0.1 0.1 0.1
}
WoodenBox {
  translation -0.351374 0.238716 0.05
  name "wooden box(1)"
  size 0.1 0.1 0.1
}
Solid {
  translation -0.01 0.51 0.025
  children [
    DEF WALL_SHAPE Shape {
      appearance PBRAppearance {
        baseColor 0.219608 0.105882 0.0901961
        roughness 1
        metalness 0
      }
      geometry Box {
        size 1.02 0.02 0.05
      }
    }
  ]
  name "WALL_1"
  boundingObject USE WALL_SHAPE
}
Solid {
  translation 0.01 -0.51 0.025
  children [
    USE WALL_SHAPE
  ]
  name "WALL_2"
  boundingObject USE WALL_SHAPE
}
Solid {
  translation 0.51 0.01 0.025
  rotation 0 0 1 -1.5707953071795862
  children [
    USE WALL_SHAPE
  ]
  name "WALL_3"
  boundingObject USE WALL_SHAPE
}
Solid {
  translation -0.51 -0.01 0.025
  rotation 0 0 1 -1.5707953071795862
  children [
    USE WALL_SHAPE
  ]
  name "WALL_4"
  boundingObject USE WALL_SHAPE
}
Robot {
  translation 0.13768692888207892 0.17186370281297383 0.039860489649126155
  rotation -1.7339834128911738e-07 4.645348277388331e-08 -0.9999999999999839 0.5235953301247088
  children [
    DEF DS_LEFT DistanceSensor {
      translation 0.1 0.03 0
      rotation 0 0 1 0.03
      children [
        Shape {
          appearance Fabric {
            IBLStrength 10
          }
          geometry Box {
            size 0.01 0.01 0.01
          }
        }
      ]
      name "ds_left"
    }
    DEF DS_RIGHT DistanceSensor {
      translation 0.1 -0.03 0
      rotation 0 0 1 -0.03
      children [
        Shape {
          appearance Fabric {
            IBLStrength 10
          }
          geometry Box {
            size 0.01 0.01 0.01
          }
        }
      ]
      name "ds_right"
    }
    DEF BODY Shape {
      appearance ThreadMetalPlate {
      }
      geometry Box {
        size 0.2 0.1 0.05
      }
    }
    DEF WHEEL_1 HingeJoint {
      jointParameters HingeJointParameters {
        position 6.527860728309612
        axis 0 1 0
        anchor 0.05 0.06 0
      }
      device [
        RotationalMotor {
          name "wheel_1"
        }
      ]
      endPoint Solid {
        translation 0.05 0.06 0
        rotation -0.9852173070389241 -0.12113370735254109 0.12113415230231032 4.697492812250665
        children [
          DEF WHEEL Shape {
            appearance GenericTireAppearance {
            }
            geometry Cylinder {
              height 0.02
              radius 0.04
              subdivision 24
            }
          }
        ]
        name "wheel_1"
        boundingObject USE WHEEL
        physics Physics {
        }
      }
    }
    DEF WHEEL_2 HingeJoint {
      jointParameters HingeJointParameters {
        position 6.527860728445232
        axis 0 1 0
        anchor 0.05 -0.06 0
      }
      device [
        RotationalMotor {
          name "wheel_2"
        }
      ]
      endPoint Solid {
        translation 0.05 -0.06 0
        rotation -0.985217307022737 -0.12113370741836811 0.12113415236813738 4.697492812234238
        children [
          USE WHEEL
        ]
        name "wheel_2"
        boundingObject USE WHEEL
        physics Physics {
        }
      }
    }
    DEF WHEEL_3 HingeJoint {
      jointParameters HingeJointParameters {
        position 6.527860728309292
        axis 0 1 0
        anchor -0.05 0.06 0
      }
      device [
        RotationalMotor {
          name "wheel_3"
        }
      ]
      endPoint Solid {
        translation -0.05 0.06 0
        rotation -0.9852173070389622 -0.12113370735238518 0.12113415230215525 4.697492812250704
        children [
          USE WHEEL
        ]
        name "wheel_3"
        boundingObject USE WHEEL
        physics Physics {
        }
      }
    }
    DEF WHEEL_4 HingeJoint {
      jointParameters HingeJointParameters {
        position 6.527860728444911
        axis 0 1 0
        anchor -0.05 -0.06 0
      }
      device [
        RotationalMotor {
          name "wheel_4"
        }
      ]
      endPoint Solid {
        translation -0.05 -0.06 0
        rotation -0.9852173070227753 -0.12113370741821207 0.12113415236798183 4.697492812234276
        children [
          USE WHEEL
        ]
        name "wheel_4"
        boundingObject USE WHEEL
        physics Physics {
        }
      }
    }
  ]
  boundingObject USE BODY
  physics Physics {
  }
  controller "four_wheels_avoid_collision"
}
FourWheelsRobot {
  hidden position_0_0 6.782745609475652e-12
  hidden position_0_1 -6.782675544983489e-12
  hidden position_0_2 6.783319409301778e-12
  hidden position_0_3 -6.782781184095729e-12
  translation 0.04986949729063513 -0.32720600270934064 0.03986048964911146
  rotation -1.9837502489378502e-08 -4.789166334810252e-08 0.9999999999999986 2.3561899999997964
}
