#VRML_SIM R2023b utf8

EXTERNPROTO "https://raw.githubusercontent.com/cyberbotics/webots/R2023b/projects/objects/backgrounds/protos/TexturedBackground.proto"
EXTERNPROTO "https://raw.githubusercontent.com/cyberbotics/webots/R2023b/projects/objects/backgrounds/protos/TexturedBackgroundLight.proto"
EXTERNPROTO "https://raw.githubusercontent.com/cyberbotics/webots/R2023b/projects/objects/floors/protos/RectangleArena.proto"
EXTERNPROTO "https://raw.githubusercontent.com/cyberbotics/webots/R2023b/projects/objects/fruits/protos/Apple.proto"

WorldInfo {
  info [
    "Simple Navigation to a Target using Camera"
  ]
  title "Simple Navigation"
}
Viewpoint {
  orientation -0.32037070126149175 -0.16841010357902028 0.93220204397208 4.052886142565406
  position 1.1660499186212234 1.571278924624266 1.546890087532802
}
TexturedBackground {
}
TexturedBackgroundLight {
}
RectangleArena {
  floorSize 1.5 1.5
}
DEF TARGET2_1 Apple {
  translation 0.130828 0.266603 0.04976456000000001
  rotation -0.13023820170165804 -0.9885015353459079 -0.07682919650953761 1.6923430563657316
}
DEF TARGET2_1 Apple {
  translation -0.183394 -0.409668 0.0497645600393127
  rotation -0.13023820170165804 -0.9885015353459079 -0.07682919650953761 1.6923430563657316
  name "apple(1)"
}
DEF TARGET_1 Solid {
  translation -0.485226 0.537977 0.04917815936182092
  rotation 0.9762222877629936 -0.04829876452757953 0.211322677959315 -2.1367300053676272
  children [
    DEF TARGET_SHAPE Shape {
      appearance PBRAppearance {
        baseColor 1 0 0
        roughness 1
        metalness 0
      }
      geometry Sphere {
        radius 0.05
        subdivision 2
      }
    }
  ]
  name "Target"
  model "target_1"
  boundingObject USE TARGET_SHAPE
  physics Physics {
    damping Damping {
    }
  }
  recognitionColors [
    0.666667 0 0
  ]
}
DEF TARGET_2 Solid {
  translation 0.136021 -0.210544 0.049178159401044766
  rotation 0.9762222877629936 -0.04829876452757953 0.211322677959315 -2.1367300053676272
  children [
    DEF TARGET_SHAPE Shape {
      appearance PBRAppearance {
        baseColor 1 0 0
        roughness 1
        metalness 0
      }
      geometry Sphere {
        radius 0.05
        subdivision 2
      }
    }
  ]
  name "Target(1)"
  model "target_2"
  boundingObject USE TARGET_SHAPE
  physics Physics {
    damping Damping {
    }
  }
  recognitionColors [
    0.666667 0 0
  ]
}
Robot {
  translation -0.5912347141931845 -0.03026246706094393 -0.00023420748536638614
  rotation -0.014121838568203569 -0.044720364276457 0.9988997260458302 3
  children [
    Pose {
      translation 0 0 0.0415
      children [
        Shape {
          appearance PBRAppearance {
            baseColor 0.0820075 0.364731 0.8
            roughness 1
            metalness 0
          }
          geometry DEF BODY Cylinder {
            height 0.08
            radius 0.045
          }
        }
      ]
    }
    HingeJoint {
      jointParameters HingeJointParameters {
        position -49.813891484383724
        axis 0 1 0
        anchor 0 0 0.025
      }
      device [
        RotationalMotor {
          name "left wheel motor"
          consumptionFactor 70
        }
        PositionSensor {
          name "left wheel sensor"
        }
      ]
      endPoint Solid {
        translation 0 0.04500000000000004 0.025
        rotation 0 -1 0 4.533079026947032
        children [
          DEF WHEEL Pose {
            rotation -1 0 0 1.57
            children [
              Shape {
                appearance PBRAppearance {
                  baseColor 1 0 0
                  roughness 1
                  metalness 0
                }
                geometry Cylinder {
                  height 0.01
                  radius 0.025
                }
              }
            ]
          }
        ]
        name "left wheel"
        boundingObject USE WHEEL
        physics DEF PHYSICS_WHEEL Physics {
          density -1
          mass 0.05
        }
      }
    }
    HingeJoint {
      jointParameters HingeJointParameters {
        position 49.81388558572791
        axis 0 1 0
        anchor 0 0 0.025
      }
      device [
        RotationalMotor {
          name "right wheel motor"
          consumptionFactor 70
        }
        PositionSensor {
          name "right wheel sensor"
        }
      ]
      endPoint Solid {
        translation 0 -0.04500000000000003 0.025
        rotation 0 -1 0 5.038946871708783
        children [
          USE WHEEL
        ]
        name "right wheel"
        boundingObject USE WHEEL
        physics USE PHYSICS_WHEEL
      }
    }
    DistanceSensor {
      translation 0.042 0.02 0.063
      rotation 0 0 -1 -0.499205
      children [
        DEF SENSOR Pose {
          rotation 0 1 0 1.57
          children [
            Shape {
              appearance PBRAppearance {
                baseColor 0.975691 0.981481 0.0252992
                roughness 1
                metalness 0
              }
              geometry Cylinder {
                height 0.004
                radius 0.008
              }
            }
          ]
        }
      ]
      name "ds0"
      lookupTable [
        0 1024 0
        0.05 1024 0
        0.15 0 0
      ]
      numberOfRays 2
      aperture 1
    }
    DistanceSensor {
      translation 0.042 -0.02 0.063
      rotation 0 0 1 -0.500795
      children [
        USE SENSOR
      ]
      name "ds1"
      lookupTable [
        0 1024 0
        0.05 1024 0
        0.15 0 0
      ]
      numberOfRays 2
      aperture 1
    }
    Shape {
      appearance PBRAppearance {
        baseColor 0.8 0.8 0.8
        baseColorMap ImageTexture {
          url [
            "https://raw.githubusercontent.com/cyberbotics/webots/R2023b/projects/samples/devices/worlds/textures/mybot.png"
          ]
        }
        roughness 0.5
        metalness 0
      }
      geometry IndexedFaceSet {
        coord Coordinate {
          point [
            0.0435 -0.015 0.038
            0.0435 -0.015 0.023
            0.0455 0 0.023
            0.0435 0.015 0.023
            0.0435 0.015 0.038
            0.0455 0 0.038
          ]
        }
        texCoord TextureCoordinate {
          point [
            0 0
            0.5 0
            1 0
            1 1
            0.5 1
            0 1
          ]
        }
        coordIndex [
          0, 1, 2, 5, -1, 5, 2, 3, 4, -1
        ]
        texCoordIndex [
          5, 0, 1, 4, -1, 4, 1, 2, 3, -1
        ]
        creaseAngle 0.9
      }
    }
    Camera {
      translation 0.04 0 0.0915
      children [
        Pose {
          translation -0.015 0 0
          rotation 0 -1 0 1.57
          children [
            Shape {
              appearance PBRAppearance {
                roughness 1
                metalness 0
              }
              geometry Cylinder {
                height 0.03
                radius 0.01
              }
            }
          ]
        }
      ]
      fieldOfView 1.0472
      width 256
      height 128
      antiAliasing TRUE
      recognition Recognition {
        frameColor 0.929412 0.831373 0
        frameThickness 3
        segmentation TRUE
      }
    }
    Display {
      name "segmented image display"
      width 256
      height 128
    }
  ]
  name "MyBot"
  boundingObject Pose {
    translation 0 0 0.0415
    children [
      USE BODY
    ]
  }
  physics Physics {
    density -1
    mass 0.5
  }
  controller "finder_controller"
  supervisor TRUE
}
